<mujoco model="dexbot">
  <compiler angle="radian" meshdir="../meshes/" eulerseq="zyx"/>
  <statistic meansize="0.153252" extent="1.90054" center="-0.0164687 0.00444038 -0.0159783"/>
    <option timestep='0.001' iterations='50' solver='PGS' gravity='0 0 -9.81'>
    <flag sensornoise="enable" frictionloss="enable"/>
    </option>
    <size njmax="500" nconmax="100" />

    <visual>
        <quality shadowsize='4096'/>
        <map znear='0.05'/>
    </visual>

    <default>
        <joint limited='true'/>
        <motor ctrllimited='true'/>
        <geom  condim='4' contype="1" conaffinity="15" solref='0.001 2' friction='0.9 0.2 0.2'/>
        <equality solref='0.001 2'/>
        <default class='visualgeom'>
            <geom material='visualgeom' condim='1' contype='0' conaffinity='0'/>
        </default>
        <default class='visualgeom2'>
            <geom material='visualgeom2' condim='1' contype='0' conaffinity='0'/>
        </default>
        <default class='obstacle'>
            <geom material='obstacle' condim='3' contype='1' conaffinity='15'/>
        </default>


        <default class='neck_joint_param'>
            <joint  damping="0.01" frictionloss="0.01" armature="0.01"/>
        </default>

        <default class='waist_joint_param'>
            <joint  damping="2" frictionloss="2" armature="0.01"/>
        </default>

        <default class='leg_joint_param'>
            <joint  damping="0.01" frictionloss="0.01" armature="0.01"/>
        </default>

        <default class='arm_joint_param'>
            <joint  damping="1" frictionloss="1" armature="0.01"/>
        </default>

        <default class='finger_joint_param'>
            <joint  damping="0.00" frictionloss="0.00" armature="0.01"/>
        </default>
    </default>
  <asset>
    <texture type="skybox" builtin="gradient" rgb1="0.3 0.5 0.7" rgb2="0 0 0" width="512" height="512"/>
    <texture name="texplane" type="2d" builtin="checker" rgb1=".2 .3 .4" rgb2=".1 0.15 0.2"
        width="512" height="512" mark="cross" markrgb=".8 .8 .8"/>
    <texture name="texplane2" type="2d" builtin="checker" rgb1="1 0.3137 0.1843" rgb2="0.0 0.30196 0.38039"
        width="512" height="512" mark="cross" markrgb=".8 .8 .8"/>

    <material name="matplane" reflectance="0." texture="texplane" texrepeat="1 1" texuniform="true"/>
    <material name="matplane2" reflectance="0.1" texture="texplane2" texrepeat="1 1" texuniform="true"/>

    <material name='obstacle'  rgba='0.9 0.6 0.2 1'/>
    <material name='visualgeom'  rgba='0.5 0.9 0.2 1'/>
    <material name='visualgeom2'  rgba='0.5 0.9 0.2 1'/>

    <mesh name="base_link" file="base_link.STL"/>
    <mesh name="leg_l1_link" file="leg_l1_link.STL"/>
    <mesh name="leg_l2_link" file="leg_l2_link.STL"/>
    <mesh name="leg_l3_link" file="leg_l3_link.STL"/>
    <mesh name="leg_l4_link" file="leg_l4_link.STL"/>
    <mesh name="leg_l5_link" file="leg_l5_link.STL"/>
    <mesh name="leg_l6_link" file="leg_l6_link.STL"/>
    <mesh name="leg_r1_link" file="leg_r1_link.STL"/>
    <mesh name="leg_r2_link" file="leg_r2_link.STL"/>
    <mesh name="leg_r3_link" file="leg_r3_link.STL"/>
    <mesh name="leg_r4_link" file="leg_r4_link.STL"/>
    <mesh name="leg_r5_link" file="leg_r5_link.STL"/>
    <mesh name="leg_r6_link" file="leg_r6_link.STL"/>
    <mesh name="waist_yaw_link" file="waist_yaw_link.STL"/>
    <mesh name="waist_roll_link" file="waist_roll_link.STL"/>
    <mesh name="waist_pitch_link" file="waist_pitch_link.STL"/>
    <mesh name="arm_l1_link" file="arm_l1_link.STL"/>
    <mesh name="arm_l2_link" file="arm_l2_link.STL"/>
    <mesh name="arm_l3_link" file="arm_l3_link.STL"/>
    <mesh name="arm_l4_link" file="arm_l4_link.STL"/>
    <mesh name="arm_l5_link" file="arm_l5_link.STL"/>
    <mesh name="arm_l6_link" file="arm_l6_link.STL"/>
    <mesh name="arm_l7_link" file="arm_l7_link.STL"/>
    <mesh name="arm_r1_link" file="arm_r1_link.STL"/>
    <mesh name="arm_r2_link" file="arm_r2_link.STL"/>
    <mesh name="arm_r3_link" file="arm_r3_link.STL"/>
    <mesh name="arm_r4_link" file="arm_r4_link.STL"/>
    <mesh name="arm_r5_link" file="arm_r5_link.STL"/>
    <mesh name="arm_r6_link" file="arm_r6_link.STL"/>
    <mesh name="arm_r7_link" file="arm_r7_link.STL"/>

    <hfield name='hf0' nrow='200' ncol='200' size="10 5 0.2 .1"/>
  </asset>
  <worldbody>
    <light directional="true" diffuse=".4 .4 .4" specular="0.1 0.1 0.1" pos="0 0 5.0" dir="0 0 -1" castshadow="false"/>
	<light directional="true" diffuse=".6 .6 .6" specular="0.2 0.2 0.2" pos="0 0 4" dir="0 0 -1"/>
	<geom name="ground" type="plane" size="0 0 1" pos="0.001 0 0" quat="1 0 0 0" material="matplane" condim="1" conaffinity="15"/>

    <body name="base_link" pos="0.0 0.0 0.8 ">
      <joint type='slide' axis='1 0 0' limited='false' />
      <joint type='slide' axis='0 1 0' limited='false' />
      <joint type='slide' axis='0 0 1' limited='false' />
      <joint type='ball' limited='false' />
      <site name='imu' size='0.01' pos='0.0 0 0.0'/>

    <geom type="mesh" contype="0" conaffinity="0" group="1" density="0" rgba="1 1 1 1" mesh="base_link"/>
<!--    <geom size="0.025 0.025 0.025" type="box" rgba="1 1 1 1"/>-->
    <geom type="mesh" rgba="1 1 1 1" mesh="base_link"/>
    <geom pos="0 0 0.068702" type="mesh" contype="0" conaffinity="0" group="1" density="0" rgba="0.752941 0.752941 0.752941 1" mesh="waist_yaw_link"/>
    <geom pos="0 0 0.068702" type="mesh" rgba="0.752941 0.752941 0.752941 1" mesh="waist_yaw_link"/>
    <geom pos="0 0 0.081702" type="mesh" contype="0" conaffinity="0" group="1" density="0" rgba="0.752941 0.752941 0.752941 1" mesh="waist_roll_link"/>
    <geom pos="0 0 0.081702" type="mesh" rgba="0.752941 0.752941 0.752941 1" mesh="waist_roll_link"/>
    <geom pos="0 0 0.095702" type="mesh" contype="0" conaffinity="0" group="1" density="0" rgba="0.752941 0.752941 0.752941 1" mesh="waist_pitch_link"/>
    <geom pos="0 0 0.095702" type="mesh" rgba="0.752941 0.752941 0.752941 1" mesh="waist_pitch_link"/>
    <geom pos="0 0.144 0.475702" quat="0.980067 0 0.198669 0" type="mesh" contype="0" conaffinity="0" group="1" density="0" rgba="0.752941 0.752941 0.752941 1" mesh="arm_l1_link"/>
    <geom pos="0 0.144 0.475702" quat="0.980067 0 0.198669 0" type="mesh" rgba="0.752941 0.752941 0.752941 1" mesh="arm_l1_link"/>
    <geom pos="-0.000921061 0.24 0.476091" quat="0.980067 0 0.198669 0" type="mesh" contype="0" conaffinity="0" group="1" density="0" rgba="0.752941 0.752941 0.752941 1" mesh="arm_l2_link"/>
    <geom pos="-0.000921061 0.24 0.476091" quat="0.980067 0 0.198669 0" type="mesh" rgba="0.752941 0.752941 0.752941 1" mesh="arm_l2_link"/>
    <geom pos="-0.0373853 0.24 0.387277" quat="0.980067 0 0.198669 0" type="mesh" contype="0" conaffinity="0" group="1" density="0" rgba="0.752941 0.752941 0.752941 1" mesh="arm_l3_link"/>
    <geom pos="-0.0373853 0.24 0.387277" quat="0.980067 0 0.198669 0" type="mesh" rgba="0.752941 0.752941 0.752941 1" mesh="arm_l3_link"/>
    <geom pos="-0.09616 0.239427 0.244928" quat="0.825336 0 -0.564642 0" type="mesh" contype="0" conaffinity="0" group="1" density="0" rgba="0.752941 0.752941 0.752941 1" mesh="arm_l4_link"/>
    <geom pos="-0.09616 0.239427 0.244928" quat="0.825336 0 -0.564642 0" type="mesh" rgba="0.752941 0.752941 0.752941 1" mesh="arm_l4_link"/>
    <geom pos="-0.0234582 0.238424 0.216663" quat="0.825336 0 -0.564642 0" type="mesh" contype="0" conaffinity="0" group="1" density="0" rgba="0.752941 0.752941 0.752941 1" mesh="arm_l5_link"/>
    <geom pos="-0.0234582 0.238424 0.216663" quat="0.825336 0 -0.564642 0" type="mesh" rgba="0.752941 0.752941 0.752941 1" mesh="arm_l5_link"/>
    <geom pos="0.136853 0.238424 0.154338" quat="0.825336 0 -0.564642 0" type="mesh" contype="0" conaffinity="0" group="1" density="0" rgba="0.752941 0.752941 0.752941 1" mesh="arm_l6_link"/>
    <geom pos="0.136853 0.238424 0.154338" quat="0.825336 0 -0.564642 0" type="mesh" rgba="0.752941 0.752941 0.752941 1" mesh="arm_l6_link"/>
    <geom pos="0.136853 0.238424 0.154338" quat="0.825336 0 -0.564642 0" type="mesh" contype="0" conaffinity="0" group="1" density="0" rgba="0.752941 0.752941 0.752941 1" mesh="arm_l7_link"/>
    <geom pos="0.136853 0.238424 0.154338" quat="0.825336 0 -0.564642 0" type="mesh" rgba="0.752941 0.752941 0.752941 1" mesh="arm_l7_link"/>
    <geom pos="0 -0.144 0.475702" quat="0.980067 0 0.198669 0" type="mesh" contype="0" conaffinity="0" group="1" density="0" rgba="0.752941 0.752941 0.752941 1" mesh="arm_r1_link"/>
    <geom pos="0 -0.144 0.475702" quat="0.980067 0 0.198669 0" type="mesh" rgba="0.752941 0.752941 0.752941 1" mesh="arm_r1_link"/>
    <geom pos="-0.000921061 -0.24 0.476091" quat="0.980067 0 0.198669 0" type="mesh" contype="0" conaffinity="0" group="1" density="0" rgba="0.752941 0.752941 0.752941 1" mesh="arm_r2_link"/>
    <geom pos="-0.000921061 -0.24 0.476091" quat="0.980067 0 0.198669 0" type="mesh" rgba="0.752941 0.752941 0.752941 1" mesh="arm_r2_link"/>
    <geom pos="-0.0373853 -0.24 0.387277" quat="0.980067 0 0.198669 0" type="mesh" contype="0" conaffinity="0" group="1" density="0" rgba="0.752941 0.752941 0.752941 1" mesh="arm_r3_link"/>
    <geom pos="-0.0373853 -0.24 0.387277" quat="0.980067 0 0.198669 0" type="mesh" rgba="0.752941 0.752941 0.752941 1" mesh="arm_r3_link"/>
    <geom pos="-0.0973558 -0.238997 0.245434" quat="0.825336 0 -0.564642 0" type="mesh" contype="0" conaffinity="0" group="1" density="0" rgba="0.752941 0.752941 0.752941 1" mesh="arm_r4_link"/>
    <geom pos="-0.0973558 -0.238997 0.245434" quat="0.825336 0 -0.564642 0" type="mesh" rgba="0.752941 0.752941 0.752941 1" mesh="arm_r4_link"/>
    <geom pos="-0.0246567 -0.239997 0.21717" quat="0.825336 0 -0.564642 0" type="mesh" contype="0" conaffinity="0" group="1" density="0" rgba="0.752941 0.752941 0.752941 1" mesh="arm_r5_link"/>
    <geom pos="-0.0246567 -0.239997 0.21717" quat="0.825336 0 -0.564642 0" type="mesh" rgba="0.752941 0.752941 0.752941 1" mesh="arm_r5_link"/>
    <geom pos="0.135654 -0.239997 0.154845" quat="0.825336 0 -0.564642 0" type="mesh" contype="0" conaffinity="0" group="1" density="0" rgba="0.752941 0.752941 0.752941 1" mesh="arm_r6_link"/>
    <geom pos="0.135654 -0.239997 0.154845" quat="0.825336 0 -0.564642 0" type="mesh" rgba="0.752941 0.752941 0.752941 1" mesh="arm_r6_link"/>
    <geom pos="0.135654 -0.239997 0.154845" quat="0.825336 0 -0.564642 0" type="mesh" contype="0" conaffinity="0" group="1" density="0" rgba="0.752941 0.752941 0.752941 1" mesh="arm_r7_link"/>
    <geom pos="0.135654 -0.239997 0.154845" quat="0.825336 0 -0.564642 0" type="mesh" rgba="0.752941 0.752941 0.752941 1" mesh="arm_r7_link"/>
    <body name="leg_l1_link" pos="0 0.046765 -0.047489" quat="0.980067 0 -0.198669 0">
      <inertial pos="0.00178647 0.116806 -0.0673005" quat="0.87669 0.480414 0.0209688 0.0132803" mass="2.52127" diaginertia="0.00489602 0.00412339 0.00392636"/>
      <joint name="leg_l1_joint" pos="0 0 0" axis="0 0.866027 -0.499998" range="-2.878 2.878" class="leg_joint_param"/>
      <geom type="mesh" contype="0" conaffinity="0" group="1" density="0" rgba="0.752941 0.752941 0.752941 1" mesh="leg_l1_link"/>
      <geom type="mesh" rgba="0.752941 0.752941 0.752941 1" mesh="leg_l1_link" class="visualgeom"/>
      <body name="leg_l2_link" pos="0 0.12298 -0.071">
        <inertial pos="0.0181612 7.56913e-07 -0.100016" quat="0.97021 -5.37082e-06 0.242267 2.26373e-06" mass="1.73505" diaginertia="0.00445392 0.00413227 0.00219163"/>
        <joint name="leg_l2_joint" pos="0 0 0" axis="1 0 0" range="-0.523 3.663" class="leg_joint_param"/>
        <geom type="mesh" contype="0" conaffinity="0" group="1" density="0" rgba="0.752941 0.752941 0.752941 1" mesh="leg_l2_link"/>
        <geom type="mesh" rgba="0.752941 0.752941 0.752941 1" mesh="leg_l2_link" class="visualgeom"/>
        <body name="leg_l3_link" pos="0 0 -0.167">
          <inertial pos="0.000114525 0.00164777 -0.147067" quat="0.744893 -0.00149019 -0.011042 0.667091" mass="2.61657" diaginertia="0.00841232 0.0078166 0.00374285"/>
          <joint name="leg_l3_joint" pos="0 0 0" axis="0 0 1" range="-2.791 2.791" class="leg_joint_param"/>
          <geom type="mesh" contype="0" conaffinity="0" group="1" density="0" rgba="0.752941 0.752941 0.752941 1" mesh="leg_l3_link"/>
          <geom type="mesh" rgba="0.752941 0.752941 0.752941 1" mesh="leg_l3_link" class="visualgeom"/>
          <body name="leg_l4_link" pos="0 0 -0.173" quat="0.889293 0 0.457338 0">
            <inertial pos="-2.42788e-08 0.00822938 -0.173855" quat="0.999139 -0.0414844 0 0" mass="3.31555" diaginertia="0.0195881 0.0193045 0.00397491"/>
            <joint name="leg_l4_joint" pos="0 0 0" axis="0 1 0" range="-2.355 2.355" class="leg_joint_param"/>
            <geom type="mesh" contype="0" conaffinity="0" group="1" density="0" rgba="0.752941 0.752941 0.752941 1" mesh="leg_l4_link"/>
<!--            <geom size="0.05 0.05 0.1" type="box" rgba="0.752941 0.752941 0.752941 1" class="visualgeom"/>-->
            <geom type="mesh" rgba="0.752941 0.752941 0.752941 1" mesh="leg_l4_link" class="visualgeom"/>
            <body name="leg_l5_link" pos="0 0 -0.34" quat="0.962425 0 -0.271547 0">
              <inertial pos="4.0016e-05 -1.65303e-05 -0.00782115" quat="0.293598 0.643273 0.643273 0.293598" mass="0.0752653" diaginertia="1.554e-05 1.55214e-05 1.52386e-05"/>
              <joint name="leg_l5_joint" pos="0 0 0" axis="0 1 0" range="-1.046 0.436" class="leg_joint_param" frictionloss="0.05"/>
              <geom type="mesh" contype="0" conaffinity="0" group="1" density="0" rgba="0.752941 0.752941 0.752941 1" mesh="leg_l5_link"/>
              <geom type="mesh" rgba="0.752941 0.752941 0.752941 1" mesh="leg_l5_link" class="visualgeom"/>
              <body name="leg_l6_link" pos="0 0 -0.015">
                <inertial pos="0.0457873 -6.33583e-09 -0.0382687" quat="0 0.723184 0 0.690656" mass="0.536406" diaginertia="0.00177828 0.00162803 0.000301376"/>
                <joint name="leg_l6_joint" pos="0 0 0" axis="1 0 0" range="-0.261 0.261" class="leg_joint_param" frictionloss="0.05"/>
                <geom type="mesh" contype="0" conaffinity="0" group="1" density="0" rgba="0.752941 0.752941 0.752941 1" mesh="leg_l6_link"/>
                <geom type="mesh" rgba="0.752941 0.752941 0.752941 1" mesh="leg_l6_link"/>
              </body>
            </body>
          </body>
        </body>
      </body>
    </body>
    <body name="leg_r1_link" pos="0 -0.046765 -0.047489" quat="0.980067 0 -0.198669 0">
      <inertial pos="0.00178614 -0.116806 -0.067301" quat="0.480617 0.876579 -0.0132454 -0.020975" mass="2.52127" diaginertia="0.00489601 0.00412338 0.00392637"/>
      <joint name="leg_r1_joint" pos="0 0 0" axis="0 0.866027 0.499998" range="-2.878 2.878" class="leg_joint_param"/>
      <geom type="mesh" contype="0" conaffinity="0" group="1" density="0" rgba="0.752941 0.752941 0.752941 1" mesh="leg_r1_link"/>
      <geom type="mesh" rgba="0.752941 0.752941 0.752941 1" mesh="leg_r1_link" class="visualgeom"/>
      <body name="leg_r2_link" pos="0 -0.12298 -0.071">
        <inertial pos="0.0181612 7.56913e-07 -0.100016" quat="0.97021 -5.37082e-06 0.242267 2.26373e-06" mass="1.73505" diaginertia="0.00445392 0.00413227 0.00219163"/>
        <joint name="leg_r2_joint" pos="0 0 0" axis="1 0 0" range="-3.663 0.523" class="leg_joint_param"/>
        <geom type="mesh" contype="0" conaffinity="0" group="1" density="0" rgba="0.752941 0.752941 0.752941 1" mesh="leg_r2_link"/>
        <geom type="mesh" rgba="0.752941 0.752941 0.752941 1" mesh="leg_r2_link" class="visualgeom"/>
        <body name="leg_r3_link" pos="0 0 -0.162">
          <inertial pos="0.000114525 -0.00164777 -0.152066" quat="0.667089 -0.0110532 -0.00149604 0.744895" mass="2.61657" diaginertia="0.00841227 0.00781656 0.00374285"/>
          <joint name="leg_r3_joint" pos="0 0 0" axis="0 0 1" range="-2.791 2.791" class="leg_joint_param"/>
          <geom type="mesh" contype="0" conaffinity="0" group="1" density="0" rgba="0.752941 0.752941 0.752941 1" mesh="leg_r3_link"/>
          <geom type="mesh" rgba="0.752941 0.752941 0.752941 1" mesh="leg_r3_link" class="visualgeom"/>
          <body name="leg_r4_link" pos="0 0 -0.178" quat="0.889293 0 0.457338 0">
            <inertial pos="2.42791e-08 -0.00822938 -0.173855" quat="0.999139 0.0414844 0 0" mass="3.31555" diaginertia="0.0195881 0.0193045 0.00397491"/>
            <joint name="leg_r4_joint" pos="0 0 0" axis="0 1 0" range="-2.355 2.355" class="leg_joint_param"/>
            <geom type="mesh" contype="0" conaffinity="0" group="1" density="0" rgba="0.752941 0.752941 0.752941 1" mesh="leg_r4_link"/>
<!--            <geom size="0.05 0.05 0.1" type="box" rgba="0.752941 0.752941 0.752941 1" class="visualgeom"/>-->
            <geom type="mesh" rgba="0.752941 0.752941 0.752941 1" mesh="leg_r4_link" class="visualgeom"/>
            <body name="leg_r5_link" pos="0 0 -0.34" quat="0.962425 0 -0.271547 0">
              <inertial pos="4.0016e-05 1.65303e-05 -0.00782115" quat="0.293598 0.643273 0.643273 0.293598" mass="0.0752653" diaginertia="1.554e-05 1.55214e-05 1.52386e-05"/>
              <joint name="leg_r5_joint" pos="0 0 0" axis="0 1 0" range="-1.046 0.436" class="leg_joint_param" frictionloss="0.05"/>
              <geom type="mesh" contype="0" conaffinity="0" group="1" density="0" rgba="0.752941 0.752941 0.752941 1" mesh="leg_r5_link"/>
              <geom type="mesh" rgba="0.752941 0.752941 0.752941 1" mesh="leg_r5_link" class="visualgeom"/>
              <body name="leg_r6_link" pos="0 0 -0.015">
                <inertial pos="0.0457873 -6.33582e-09 -0.0382687" quat="0 0.723184 0 0.690656" mass="0.536406" diaginertia="0.00177828 0.00162803 0.000301376"/>
                <joint name="leg_r6_joint" pos="0 0 0" axis="1 0 0" range="-0.261 0.261" class="leg_joint_param" frictionloss="0.05"/>
                <geom type="mesh" contype="0" conaffinity="0" group="1" density="0" rgba="0.752941 0.752941 0.752941 1" mesh="leg_r6_link"/>
                <geom type="mesh" rgba="0.752941 0.752941 0.752941 1" mesh="leg_r6_link"/>
              </body>
            </body>
          </body>
        </body>
      </body>
    </body>
   </body>
  </worldbody>

  <actuator>
	<motor name="leg_l1_joint" joint="leg_l1_joint" gear="1" ctrllimited="true" ctrlrange="-360 360"/>
	<motor name="leg_l2_joint" joint="leg_l2_joint" gear="1" ctrllimited="true" ctrlrange="-360 360"/>
	<motor name="leg_l3_joint" joint="leg_l3_joint" gear="1" ctrllimited="true" ctrlrange="-120 120"/>
	<motor name="leg_l4_joint" joint="leg_l4_joint" gear="1" ctrllimited="true" ctrlrange="-360 360"/>
	<motor name="leg_l5_joint" joint="leg_l5_joint" gear="1" ctrllimited="true" ctrlrange="-120 120"/>
	<motor name="leg_l6_joint" joint="leg_l6_joint" gear="1" ctrllimited="true" ctrlrange="-120 120"/>
	<motor name="leg_r1_joint" joint="leg_r1_joint" gear="1" ctrllimited="true" ctrlrange="-360 360"/>
	<motor name="leg_r2_joint" joint="leg_r2_joint" gear="1" ctrllimited="true" ctrlrange="-360 360"/>
	<motor name="leg_r3_joint" joint="leg_r3_joint" gear="1" ctrllimited="true" ctrlrange="-120 120"/>
	<motor name="leg_r4_joint" joint="leg_r4_joint" gear="1" ctrllimited="true" ctrlrange="-360 360"/>
	<motor name="leg_r5_joint" joint="leg_r5_joint" gear="1" ctrllimited="true" ctrlrange="-120 120"/>
	<motor name="leg_r6_joint" joint="leg_r6_joint" gear="1" ctrllimited="true" ctrlrange="-120 120"/>
  </actuator>
  <sensor>
	<actuatorpos name="leg_l2_joint_p" actuator="leg_l2_joint" user="13"/>
	<actuatorpos name="leg_l3_joint_p" actuator="leg_l3_joint" user="13"/>
	<actuatorpos name="leg_l1_joint_p" actuator="leg_l1_joint" user="13"/>
	<actuatorpos name="leg_l4_joint_p" actuator="leg_l4_joint" user="13"/>
	<actuatorpos name="leg_l5_joint_p" actuator="leg_l5_joint" user="13"/>
	<actuatorpos name="leg_l6_joint_p" actuator="leg_l6_joint" user="13"/>
	<actuatorpos name="leg_r2_joint_p" actuator="leg_r2_joint" user="13"/>
	<actuatorpos name="leg_r3_joint_p" actuator="leg_r3_joint" user="13"/>
	<actuatorpos name="leg_r1_joint_p" actuator="leg_r1_joint" user="13"/>
	<actuatorpos name="leg_r4_joint_p" actuator="leg_r4_joint" user="13"/>
	<actuatorpos name="leg_r5_joint_p" actuator="leg_r5_joint" user="13"/>
	<actuatorpos name="leg_r6_joint_p" actuator="leg_r6_joint" user="13"/>
	<actuatorvel name="leg_l2_joint_v" actuator="leg_l2_joint" user="13"/>
	<actuatorvel name="leg_l3_joint_v" actuator="leg_l3_joint" user="13"/>
	<actuatorvel name="leg_l1_joint_v" actuator="leg_l1_joint" user="13"/>
	<actuatorvel name="leg_l4_joint_v" actuator="leg_l4_joint" user="13"/>
	<actuatorvel name="leg_l5_joint_v" actuator="leg_l5_joint" user="13"/>
	<actuatorvel name="leg_l6_joint_v" actuator="leg_l6_joint" user="13"/>
	<actuatorvel name="leg_r2_joint_v" actuator="leg_r2_joint" user="13"/>
	<actuatorvel name="leg_r3_joint_v" actuator="leg_r3_joint" user="13"/>
	<actuatorvel name="leg_r1_joint_v" actuator="leg_r1_joint" user="13"/>
	<actuatorvel name="leg_r4_joint_v" actuator="leg_r4_joint" user="13"/>
	<actuatorvel name="leg_r5_joint_v" actuator="leg_r5_joint" user="13"/>
	<actuatorvel name="leg_r6_joint_v" actuator="leg_r6_joint" user="13"/>
	<actuatorfrc name="leg_l2_joint_f" actuator="leg_l2_joint" user="13" noise="1e-3"/>
	<actuatorfrc name="leg_l3_joint_f" actuator="leg_l3_joint" user="13" noise="1e-3"/>
	<actuatorfrc name="leg_l1_joint_f" actuator="leg_l1_joint" user="13" noise="1e-3"/>
	<actuatorfrc name="leg_l4_joint_f" actuator="leg_l4_joint" user="13" noise="1e-3"/>
	<actuatorfrc name="leg_l5_joint_f" actuator="leg_l5_joint" user="13" noise="1e-3"/>
	<actuatorfrc name="leg_l6_joint_f" actuator="leg_l6_joint" user="13" noise="1e-3"/>
	<actuatorfrc name="leg_r2_joint_f" actuator="leg_r2_joint" user="13" noise="1e-3"/>
	<actuatorfrc name="leg_r3_joint_f" actuator="leg_r3_joint" user="13" noise="1e-3"/>
	<actuatorfrc name="leg_r1_joint_f" actuator="leg_r1_joint" user="13" noise="1e-3"/>
	<actuatorfrc name="leg_r4_joint_f" actuator="leg_r4_joint" user="13" noise="1e-3"/>
	<actuatorfrc name="leg_r5_joint_f" actuator="leg_r5_joint" user="13" noise="1e-3"/>
	<actuatorfrc name="leg_r6_joint_f" actuator="leg_r6_joint" user="13" noise="1e-3"/>

	<framequat name="orientation" objtype="site" noise="0.001" objname="imu"/>
	<framepos name="position" objtype="site" noise="0.001" objname="imu"/>
	<gyro name="angular-velocity" site="imu" noise="0.005" cutoff="34.9"/>
	<velocimeter name="linear-velocity" site="imu" noise="0.001" cutoff="30"/>
	<accelerometer name="linear-acceleration" site="imu" noise="0.005" cutoff="157"/>
	<magnetometer name="magnetometer" site="imu"/>
  </sensor>

  <contact>
	<exclude name="//unnamed_contact_0" body1="base_link" body2="leg_l1_link"/>
	<exclude name="//unnamed_contact_1" body1="base_link" body2="leg_r1_link"/>
	<exclude name="//unnamed_contact_2" body1="base_link" body2="leg_l2_link"/>
    <exclude name="//unnamed_contact_3" body1="base_link" body2="leg_r2_link"/>
    <exclude name="//unnamed_contact_4" body1="leg_l4_link" body2="leg_l6_link"/>
    <exclude name="//unnamed_contact_5" body1="leg_r4_link" body2="leg_r6_link"/>
  </contact>
</mujoco>
